Workbook

Sheet Response review
A2: Policy response review: 143 unique responses; 37 exact repeats linked
A3: Enter scores only in yellow cells. Gray repeated rows copy the score of the identical response for the same scenario and system.
A4: Response ID | B4: Run | C4: Scenario | D4: System | E4: Actual response | F4: Criteria | G4: Items scored | H4: Items satisfied | I4: Contradiction / invention (0/1) | J4: Response result | K4: Reviewer notes
A5: P001 | B5: run_1 | C5: POLICY-001 | D5: multi_agent | E5: ตามนโยบายการคืนสินค้าของทางร้าน ยังไม่ได้ระบุระยะเวลาการได้รับเงินคืนหลังส่งสินค้าคืนไว้ชัดเจนค่ะ กรุณาสอบถามรายละเอียดเพิ่มเติมได้ทางแชทหรืออีเมล support@siamcart.demo ค่ะ | F5: 2 | G5: =COUNT('Criterion review'!G5:G6) -> 0 | H5: =SUM('Criterion review'!G5:G6) -> 0 | I5: 0 | J5: =IF(OR(G5<F5,COUNT(I5)=0),"Pending",IF(AND(H5=F5,I5=0),"Correct","Incorrect")) -> Pending
A6: P002 | B6: run_1 | C6: POLICY-002 | D6: multi_agent | E6: กรณีสินค้ามีตำหนิ ยังไม่สามารถยืนยันได้ว่าจะได้รับเงินคืนรวมค่าส่งหรือไม่นะคะ รบกวนขอข้อมูลเพิ่มเติม เช่น วันที่ได้รับสินค้า และรูปถ่ายตำหนิ เพื่อให้ทีมงานตรวจสอบให้ได้ไหมคะ | F6: 2 | G6: =COUNT('Criterion review'!G7:G8) -> 0 | H6: =SUM('Criterion review'!G7:G8) -> 0 | I6: 0 | J6: =IF(OR(G6<F6,COUNT(I6)=0),"Pending",IF(AND(H6=F6,I6=0),"Correct","Incorrect")) -> Pending
A7: P003 | B7: run_1 | C7: POLICY-003 | D7: multi_agent | E7: ตามนโยบายการคืนสินค้า คุณสามารถขอคืนสินค้าได้ภายใน 14 วันนับจากวันที่ได้รับ โดยสินค้าต้องอยู่ในสภาพเดิม ไม่มีการใช้งาน และมีบรรจุภัณฑ์ครบถ้วนค่ะ นโยบายไม่ได้ระบุค่าธรรมเนียมเพิ่มเติมในการคืน แต่หากสินค้าอยู่ในหมวดที่ไม่สามารถคืนได้ เช่น ชุดชั้นใน เครื่องสำอางที่เปิดใช้แล้ว หรือสินค้าดิจิทัลที่เปิดใช้งานแล้ว จะไม่สามารถคืนได้นะคะ หากมีข้อสงสัยเพิ่มเติม แจ้งรายละเอียดคำสั่งซื้อได้เลยค่ะ | F7: 2 | G7: =COUNT('Criterion review'!G9:G10) -> 0 | H7: =SUM('Criterion review'!G9:G10) -> 0 | I7: 1 | J7: =IF(OR(G7<F7,COUNT(I7)=0),"Pending",IF(AND(H7=F7,I7=0),"Correct","Incorrect")) -> Pending
A8: P004 | B8: run_1 | C8: POLICY-004 | D8: multi_agent | E8: จากข้อมูลที่มี ยังไม่พบรายการสินค้าที่ถูกแยกออกจากการขอคืนเงินโดยตรงค่ะ หากลูกค้าต้องการทราบรายละเอียดเพิ่มเติม กรุณาระบุประเภทสินค้าหรือสถานการณ์ให้ชัดเจน เพื่อที่ทางเราจะได้ตรวจสอบให้อีกครั้งนะคะ | F8: 3 | G8: =COUNT('Criterion review'!G11:G13) -> 0 | H8: =SUM('Criterion review'!G11:G13) -> 0 | I8: 0 | J8: =IF(OR(G8<F8,COUNT(I8)=0),"Pending",IF(AND(H8=F8,I8=0),"Correct","Incorrect")) -> Pending
A9: P005 | B9: run_1 | C9: POLICY-005 | D9: multi_agent | E9: เมื่อดำเนินการคืนเงินเสร็จสิ้น ทางร้านจะแจ้งให้ลูกค้าทราบทางอีเมลที่ลงทะเบียนไว้ค่ะ และสถานะการคืนเงินในระบบจะเปลี่ยนเป็น "Refunded" ด้วยนะคะ โดยเงินจะโอนกลับไปยังบัญชีธนาคารหรือช่องทางการชำระเงินเดิมภายใน 5-7 วันทำการหลังตรวจสอบสินค้าคืนเรียบร้อยค่ะ | F9: 2 | G9: =COUNT('Criterion review'!G14:G15) -> 0 | H9: =SUM('Criterion review'!G14:G15) -> 0 | I9: 0 | J9: =IF(OR(G9<F9,COUNT(I9)=0),"Pending",IF(AND(H9=F9,I9=0),"Correct","Incorrect")) -> Pending
A10: P006 | B10: run_1 | C10: POLICY-006 | D10: multi_agent | E10: นโยบายการคืนเงินของร้านค่ะ หากสินค้ามีตำหนิหรือไม่ตรงตามที่สั่งซื้อ ลูกค้าสามารถขอคืนเงินเต็มจำนวนรวมค่าจัดส่งได้ โดยต้องแจ้งภายใน 7 วันหลังจากได้รับสินค้าค่ะ หลังจากได้รับสินค้าคืนและตรวจสอบเรียบร้อย ทางร้านจะดำเนินการคืนเงินภายใน 5-7 วันทำการไปยังช่องทางการชำระเงินเดิม และจะแจ้งผลให้ทราบทางอีเมลที่ลงทะเบียนไว้นะคะ | F10: 2 | G10: =COUNT('Criterion review'!G16:G17) -> 0 | H10: =SUM('Criterion review'!G16:G17) -> 0 | I10: 1 | J10: =IF(OR(G10<F10,COUNT(I10)=0),"Pending",IF(AND(H10=F10,I10=0),"Correct","Incorrect")) -> Pending
A11: P007 | B11: run_1 | C11: POLICY-007 | D11: multi_agent | E11: กรุณาระบุหมายเลขคำสั่งซื้อของคุณด้วยค่ะ | F11: 2 | G11: =COUNT('Criterion review'!G18:G19) -> 0 | H11: =SUM('Criterion review'!G18:G19) -> 0 | I11: 0 | J11: =IF(OR(G11<F11,COUNT(I11)=0),"Pending",IF(AND(H11=F11,I11=0),"Correct","Incorrect")) -> Pending
A12: P008 | B12: run_1 | C12: POLICY-008 | D12: multi_agent | E12: ตามนโยบายการคืนสินค้า เครื่องสำอางที่เปิดใช้งานแล้วและชุดชั้นในไม่สามารถคืนได้ค่ะ โดยสินค้าประเภทนี้จัดอยู่ในข้อ 2 สินค้าที่ไม่สามารถคืนได้ สำหรับเสื้อผ้าและรองเท้าสามารถคืนได้ภายใน 14 วัน โดยต้องไม่ถูกใช้หรือซัก และมีป้ายติดครบถ้วนค่ะ หากมีข้อสงสัยเพิ่มเติมสามารถสอบถามได้นะคะ | F12: 3 | G12: =COUNT('Criterion review'!G20:G22) -> 0 | H12: =SUM('Criterion review'!G20:G22) -> 0 | I12: 1 | J12: =IF(OR(G12<F12,COUNT(I12)=0),"Pending",IF(AND(H12=F12,I12=0),"Correct","Incorrect")) -> Pending
A13: P009 | B13: run_1 | C13: POLICY-009 | D13: multi_agent | E13: กรุณาระบุหมายเลขคำสั่งซื้อของคุณด้วยค่ะ | F13: 2 | G13: =COUNT('Criterion review'!G23:G24) -> 0 | H13: =SUM('Criterion review'!G23:G24) -> 0 | I13: 0 | J13: =IF(OR(G13<F13,COUNT(I13)=0),"Pending",IF(AND(H13=F13,I13=0),"Correct","Incorrect")) -> Pending
A14: P010 | B14: run_1 | C14: POLICY-010 | D14: multi_agent | E14: ท่านสามารถเริ่มการคืนสินค้าได้โดยแจ้งผ่านแชทหรืออีเมล support@siamcart.demo พร้อมระบุรายละเอียดคำสั่งซื้อและเหตุผลในการคืนสินค้าค่ะ โดยสินค้าต้องอยู่ในสภาพเดิม ไม่มีการใช้งาน และอยู่ภายใน 14 วันนับตั้งแต่วันที่ได้รับสินค้านะคะ ทั้งนี้สินค้าบางประเภทไม่สามารถคืนได้ เช่น ชุดชั้นใน เครื่องสำอางที่เปิดใช้งานแล้ว หรือสินค้าดิจิทัลที่เปิดใช้งานแล้วค่ะ ทางร้านจะตอบกลับภายใน 24 ชั่วโมงทำการค่ะ | F14: 3 | G14: =COUNT('Criterion review'!G25:G27) -> 0 | H14: =SUM('Criterion review'!G25:G27) -> 0 | I14: 1 | J14: =IF(OR(G14<F14,COUNT(I14)=0),"Pending",IF(AND(H14=F14,I14=0),"Correct","Incorrect")) -> Pending
A15: P011 | B15: run_1 | C15: POLICY-011 | D15: multi_agent | E15: กรุณาระบุหมายเลขคำสั่งซื้อของคุณด้วยค่ะ | F15: 2 | G15: =COUNT('Criterion review'!G28:G29) -> 0 | H15: =SUM('Criterion review'!G28:G29) -> 0 | J15: =IF(OR(G15<F15,COUNT(I15)=0),"Pending",IF(AND(H15=F15,I15=0),"Correct","Incorrect")) -> Pending
A16: P012 | B16: run_1 | C16: POLICY-012 | D16: multi_agent | E16: ตามนโยบายของร้านค่ะ ลูกค้าสามารถขอคืนสินค้าได้ภายใน 14 วันนับจากวันที่ได้รับสินค้า โดยสินค้าต้องอยู่ในสภาพเดิม ไม่มีการใช้งาน และมีบรรจุภัณฑ์เดิมครบถ้วน ค่ะ ทั้งนี้ สินค้าบางประเภท เช่น ชุดชั้นใน เครื่องสำอางที่เปิดใช้แล้ว อาหารและเครื่องดื่มที่เปิดบรรจุภัณฑ์ และซอฟต์แวร์หรือคีย์ดิจิทัลที่เปิดใช้งานแล้ว ไม่สามารถคืนได้นะคะ หากต้องการขอคืน สามารถแจ้งผ่านแชทหรืออีเมล support@siamcart.demo พร้อมระบุรายละเอียดคำสั่งซื้อและเหตุผลได้เลยค่ะ ทางร้านจะตอบกลับภายใน 24 ชั่วโมงทำการนะคะ | F16: 2 | G16: =COUNT('Criterion review'!G30:G31) -> 0 | H16: =SUM('Criterion review'!G30:G31) -> 0 | I16: 0 | J16: =IF(OR(G16<F16,COUNT(I16)=0),"Pending",IF(AND(H16=F16,I16=0),"Correct","Incorrect")) -> Pending
A17: P013 | B17: run_1 | C17: POLICY-013 | D17: multi_agent | E17: ได้ค่ะ ลูกค้าสามารถขอเปลี่ยนสินค้าเป็นอย่างอื่นได้ภายใน 14 วันนับตั้งแต่วันที่ได้รับสินค้า โดยสินค้าต้องอยู่ในสภาพดี ไม่มีการใช้งาน และไม่มีร่องรอยความเสียหายค่ะ หากเป็นกรณีเปลี่ยนไซส์หรือสี ต้องมีป้ายและบรรจุภัณฑ์เดิมครบถ้วนนะคะ | F17: 2 | G17: =COUNT('Criterion review'!G32:G33) -> 0 | H17: =SUM('Criterion review'!G32:G33) -> 0 | I17: 1 | J17: =IF(OR(G17<F17,COUNT(I17)=0),"Pending",IF(AND(H17=F17,I17=0),"Correct","Incorrect")) -> Pending
A18: P014 | B18: run_1 | C18: POLICY-014 | D18: multi_agent | E18: สินค้าที่มีตำหนิจากการผลิต ทางร้านยินดีเปลี่ยนให้ฟรีโดยไม่มีค่าใช้จ่ายเพิ่มเติมค่ะ เพียงแต่ลูกค้าต้องแจ้งภายใน 7 วันหลังจากได้รับสินค้านะคะ หากเกินกำหนดอาจไม่สามารถดำเนินการเปลี่ยนให้ได้ค่ะ | F18: 2 | G18: =COUNT('Criterion review'!G34:G35) -> 0 | H18: =SUM('Criterion review'!G34:G35) -> 0 | I18: 0 | J18: =IF(OR(G18<F18,COUNT(I18)=0),"Pending",IF(AND(H18=F18,I18=0),"Correct","Incorrect")) -> Pending
A19: P015 | B19: run_1 | C19: POLICY-015 | D19: multi_agent | E19: กรุณาระบุหมายเลขคำสั่งซื้อของคุณด้วยค่ะ | F19: 2 | G19: =COUNT('Criterion review'!G36:G37) -> 0 | H19: =SUM('Criterion review'!G36:G37) -> 0 | I19: 1 | J19: =IF(OR(G19<F19,COUNT(I19)=0),"Pending",IF(AND(H19=F19,I19=0),"Correct","Incorrect")) -> Pending
A20: P016 | B20: run_1 | C20: POLICY-016 | D20: multi_agent | E20: สำหรับการเปลี่ยนสินค้า ค่าจัดส่งจะขึ้นอยู่กับเหตุผลค่ะ หากสินค้ามีตำหนิหรือไม่ถูกต้อง ทางร้านออกค่าจัดส่งให้ทั้งสองฝั่ง แต่หากเป็นการเปลี่ยนใจหรือเปลี่ยนไซส์ ลูกค้าออกค่าจัดส่งในการส่งสินค้าคืน และทางร้านออกค่าจัดส่งในการส่งสินค้าใหม่ให้ค่ะ | F20: 2 | G20: =COUNT('Criterion review'!G38:G39) -> 0 | H20: =SUM('Criterion review'!G38:G39) -> 0 | I20: 0 | J20: =IF(OR(G20<F20,COUNT(I20)=0),"Pending",IF(AND(H20=F20,I20=0),"Correct","Incorrect")) -> Pending
A21: P017 | B21: run_1 | C21: POLICY-017 | D21: multi_agent | E21: ยินดีช่วยตรวจสอบคำขอคืนสินค้าหรือยกเลิกคำสั่งซื้อค่ะ กรุณาระบุหมายเลขคำสั่งซื้อ ค่ะ | F21: 2 | G21: =COUNT('Criterion review'!G40:G41) -> 0 | H21: =SUM('Criterion review'!G40:G41) -> 0 | I21: 1 | J21: =IF(OR(G21<F21,COUNT(I21)=0),"Pending",IF(AND(H21=F21,I21=0),"Correct","Incorrect")) -> Pending
A22: P018 | B22: run_1 | C22: POLICY-018 | D22: multi_agent | E22: ได้ค่ะ การเปลี่ยนสินค้าขึ้นอยู่กับสต็อกสินค้าในขณะนั้น หากสินค้าหมด ทางร้านจะเสนอทางเลือกอื่นหรือคืนเงินให้ตามความเหมาะสมค่ะ กรณีเปลี่ยนใจหรือเปลี่ยนไซส์ ลูกค้าออกค่าจัดส่งในการส่งสินค้าคืน และทางร้านออกค่าจัดส่งในการส่งสินค้าใหม่ค่ะ แต่หากสินค้าเป็นประเภทที่ไม่สามารถคืนได้ เช่น ชุดชั้นใน เครื่องสำอางที่เปิดใช้แล้ว จะไม่สามารถเปลี่ยนได้นะคะ รบกวนแจ้งหมายเลขคำสั่งซื้อและเหตุผลที่ต้องการเปลี่ยนด้วยค่ะ | F22: 2 | G22: =COUNT('Criterion review'!G42:G43) -> 0 | H22: =SUM('Criterion review'!G42:G43) -> 0 | I22: 0 | J22: =IF(OR(G22<F22,COUNT(I22)=0),"Pending",IF(AND(H22=F22,I22=0),"Correct","Incorrect")) -> Pending
A23: P019 | B23: run_1 | C23: POLICY-019 | D23: multi_agent | E23: กรุณาระบุหมายเลขคำสั่งซื้อของคุณด้วยค่ะ | F23: 2 | G23: =COUNT('Criterion review'!G44:G45) -> 0 | H23: =SUM('Criterion review'!G44:G45) -> 0 | I23: 1 | J23: =IF(OR(G23<F23,COUNT(I23)=0),"Pending",IF(AND(H23=F23,I23=0),"Correct","Incorrect")) -> Pending
A24: P020 | B24: run_1 | C24: POLICY-020 | D24: multi_agent | E24: กรุณาระบุหมายเลขคำสั่งซื้อของคุณด้วยค่ะ | F24: 2 | G24: =COUNT('Criterion review'!G46:G47) -> 0 | H24: =SUM('Criterion review'!G46:G47) -> 0 | I24: 0 | J24: =IF(OR(G24<F24,COUNT(I24)=0),"Pending",IF(AND(H24=F24,I24=0),"Correct","Incorrect")) -> Pending
A25: P021 | B25: run_1 | C25: POLICY-021 | D25: multi_agent | E25: กรุณาระบุหมายเลขคำสั่งซื้อของคุณด้วยค่ะ | F25: 3 | G25: =COUNT('Criterion review'!G48:G50) -> 0 | H25: =SUM('Criterion review'!G48:G50) -> 0 | I25: 0 | J25: =IF(OR(G25<F25,COUNT(I25)=0),"Pending",IF(AND(H25=F25,I25=0),"Correct","Incorrect")) -> Pending
A26: P022 | B26: run_1 | C26: POLICY-022 | D26: multi_agent | E26: กรุณาระบุหมายเลขคำสั่งซื้อของคุณด้วยค่ะ | F26: 3 | G26: =COUNT('Criterion review'!G51:G53) -> 0 | H26: =SUM('Criterion review'!G51:G53) -> 0 | I26: 0 | J26: =IF(OR(G26<F26,COUNT(I26)=0),"Pending",IF(AND(H26=F26,I26=0),"Correct","Incorrect")) -> Pending
A27: P023 | B27: run_1 | C27: POLICY-023 | D27: multi_agent | E27: กรุณาระบุหมายเลขคำสั่งซื้อของคุณด้วยค่ะ | F27: 2 | G27: =COUNT('Criterion review'!G54:G55) -> 0 | H27: =SUM('Criterion review'!G54:G55) -> 0 | J27: =IF(OR(G27<F27,COUNT(I27)=0),"Pending",IF(AND(H27=F27,I27=0),"Correct","Incorrect")) -> Pending
A28: P024 | B28: run_1 | C28: POLICY-024 | D28: multi_agent | E28: กรุณาระบุหมายเลขคำสั่งซื้อของคุณด้วยค่ะ | F28: 2 | G28: =COUNT('Criterion review'!G56:G57) -> 0 | H28: =SUM('Criterion review'!G56:G57) -> 0 | I28: 0 | J28: =IF(OR(G28<F28,COUNT(I28)=0),"Pending",IF(AND(H28=F28,I28=0),"Correct","Incorrect")) -> Pending
A29: P025 | B29: run_1 | C29: POLICY-025 | D29: multi_agent | E29: กรุณาระบุหมายเลขคำสั่งซื้อของคุณด้วยค่ะ | F29: 1 | G29: =COUNT('Criterion review'!G58:G58) -> 0 | H29: =SUM('Criterion review'!G58:G58) -> 0 | I29: 0 | J29: =IF(OR(G29<F29,COUNT(I29)=0),"Pending",IF(AND(H29=F29,I29=0),"Correct","Incorrect")) -> Pending
A30: P026 | B30: run_1 | C30: POLICY-026 | D30: multi_agent | E30: กรุณาระบุหมายเลขคำสั่งซื้อของคุณด้วยค่ะ | F30: 2 | G30: =COUNT('Criterion review'!G59:G60) -> 0 | H30: =SUM('Criterion review'!G59:G60) -> 0 | J30: =IF(OR(G30<F30,COUNT(I30)=0),"Pending",IF(AND(H30=F30,I30=0),"Correct","Incorrect")) -> Pending
A31: P027 | B31: run_1 | C31: POLICY-027 | D31: multi_agent | E31: กรุณาระบุหมายเลขคำสั่งซื้อของคุณด้วยค่ะ | F31: 2 | G31: =COUNT('Criterion review'!G61:G62) -> 0 | H31: =SUM('Criterion review'!G61:G62) -> 0 | I31: 0 | J31: =IF(OR(G31<F31,COUNT(I31)=0),"Pending",IF(AND(H31=F31,I31=0),"Correct","Incorrect")) -> Pending
A32: P028 | B32: run_1 | C32: POLICY-028 | D32: multi_agent | E32: กรุณาระบุหมายเลขคำสั่งซื้อของคุณด้วยค่ะ | F32: 2 | G32: =COUNT('Criterion review'!G63:G64) -> 0 | H32: =SUM('Criterion review'!G63:G64) -> 0 | I32: 0 | J32: =IF(OR(G32<F32,COUNT(I32)=0),"Pending",IF(AND(H32=F32,I32=0),"Correct","Incorrect")) -> Pending
A33: P029 | B33: run_1 | C33: POLICY-029 | D33: multi_agent | E33: กรุณาระบุหมายเลขคำสั่งซื้อของคุณด้วยค่ะ | F33: 2 | G33: =COUNT('Criterion review'!G65:G66) -> 0 | H33: =SUM('Criterion review'!G65:G66) -> 0 | I33: 0 | J33: =IF(OR(G33<F33,COUNT(I33)=0),"Pending",IF(AND(H33=F33,I33=0),"Correct","Incorrect")) -> Pending
A34: P030 | B34: run_1 | C34: POLICY-030 | D34: multi_agent | E34: กรุณาระบุหมายเลขคำสั่งซื้อของคุณด้วยค่ะ | F34: 1 | G34: =COUNT('Criterion review'!G67:G67) -> 0 | H34: =SUM('Criterion review'!G67:G67) -> 0 | I34: 0 | J34: =IF(OR(G34<F34,COUNT(I34)=0),"Pending",IF(AND(H34=F34,I34=0),"Correct","Incorrect")) -> Pending
A35: P031 | B35: run_1 | C35: POLICY-001 | D35: monolithic | F35: 2 | G35: =COUNT('Criterion review'!G68:G69) -> 0 | H35: =SUM('Criterion review'!G68:G69) -> 0 | I35: 1 | J35: =IF(OR(G35<F35,COUNT(I35)=0),"Pending",IF(AND(H35=F35,I35=0),"Correct","Incorrect")) -> Pending | K35: Blank answer: verify criteria and mark 0/1; this is only a triage cue.
A36: P032 | B36: run_1 | C36: POLICY-002 | D36: monolithic | E36: ตามนโยบายการคืนเงิน หากสินค้ามีตำหนิหรือไม่ตรงตามที่สั่งซื้อ ลูกค้าสามารถขอคืนเงินเต็มจำนวนรวมค่าจัดส่งได้ โดยต้องแจ้งภายใน 7 วันหลังจากได้รับสินค้าค่ะ กรุณาแจ้งหมายเลขคำสั่งซื้อ (Order ID) เพื่อให้ตรวจสอบข้อมูลเพิ่มเติมได้นะคะ | F36: 2 | G36: =COUNT('Criterion review'!G70:G71) -> 0 | H36: =SUM('Criterion review'!G70:G71) -> 0 | I36: 0 | J36: =IF(OR(G36<F36,COUNT(I36)=0),"Pending",IF(AND(H36=F36,I36=0),"Correct","Incorrect")) -> Pending
A37: P033 | B37: run_1 | C37: POLICY-003 | D37: monolithic | E37: กรณีเปลี่ยนใจคืนสินค้า หากสินค้าอยู่ในสภาพสมบูรณ์ ไม่มีการใช้งาน และมีบรรจุภัณฑ์ครบถ้วน ลูกค้าจะได้รับเงินคืนเฉพาะราคาสินค้าเท่านั้น ไม่รวมค่าจัดส่ง และทางร้านจะหักค่าธรรมเนียมการคืนสินค้าจำนวน 50 บาทครับ | F37: 2 | G37: =COUNT('Criterion review'!G72:G73) -> 0 | H37: =SUM('Criterion review'!G72:G73) -> 0 | I37: 0 | J37: =IF(OR(G37<F37,COUNT(I37)=0),"Pending",IF(AND(H37=F37,I37=0),"Correct","Incorrect")) -> Pending
A38: P034 | B38: run_1 | C38: POLICY-004 | D38: monolithic | E38: According to our refund policy, refunds will not be issued for: items that are damaged or used by the customer; items returned after 14 days from receipt; and items that are non-returnable per the return policy. | F38: 3 | G38: =COUNT('Criterion review'!G74:G76) -> 0 | H38: =SUM('Criterion review'!G74:G76) -> 0 | I38: 0 | J38: =IF(OR(G38<F38,COUNT(I38)=0),"Pending",IF(AND(H38=F38,I38=0),"Correct","Incorrect")) -> Pending
A39: P035 | B39: run_1 | C39: POLICY-005 | D39: monolithic | E39: ตามนโยบายการคืนเงินของร้าน เมื่อดำเนินการคืนเงินเสร็จเรียบร้อยแล้ว ทางร้านจะแจ้งให้ลูกค้าทราบทางอีเมลที่ลงทะเบียนไว้ และสถานะการคืนเงินในระบบจะเปลี่ยนเป็น "Refunded" ครับ | F39: 2 | G39: =COUNT('Criterion review'!G77:G78) -> 0 | H39: =SUM('Criterion review'!G77:G78) -> 0 | I39: 0 | J39: =IF(OR(G39<F39,COUNT(I39)=0),"Pending",IF(AND(H39=F39,I39=0),"Correct","Incorrect")) -> Pending
A40: P036 | B40: run_1 | C40: POLICY-006 | D40: monolithic | E40: สวัสดีค่ะ นโยบายการคืนเงินของทางร้านโดยสรุปมีดังนี้: 1. หลังได้รับสินค้าคืนและตรวจสอบสภาพเรียบร้อยแล้ว ทางร้านจะดำเนินการคืนเงินภายใน 5-7 วันทำการ โดยโอนกลับไปยังช่องทางการชำระเงินเดิม 2. หากสินค้ามีตำหนิหรือไม่ตรงตามที่สั่งซื้อ ลูกค้าสามารถขอคืนเงินเต็มจำนวนรวมค่าจัดส่งได้ โดยต้องแจ้งภายใน 7 วันหลังจากได้รับสินค้า 3. กรณีเปลี่ยนใจและสินค้าอยู่ในสภาพสมบูรณ์ จะได้รับเงินคืนเฉพาะราคาสินค้า ไม่รวมค่าจัดส่ง และมีการหักค่าธรรมเนียมการคืนสินค้า 50 บาท 4. ไม่มีการคืนเงินสำหรับสินค้าที่ใช้แล้วหรือเสียหายจากการใช้งานของลูกค้า, คืนเกิน 14 วันนับจากวันที่ได้รับ หรือสินค้าที่ไม่สามารถคืนได้ตามนโยบาย 5. เมื่อดำเนินการคืนเงินเสร็จสิ้น ทางร้านจะแจ้งให้ทราบทางอีเมล และสถานะในระบบจะเปลี่ยนเป็น "Refunded" หากมีคำถามเพิ่มเติมสามารถสอบถามได้เลยนะคะ | F40: 2 | G40: =COUNT('Criterion review'!G79:G80) -> 0 | H40: =SUM('Criterion review'!G79:G80) -> 0 | I40: 0 | J40: =IF(OR(G40<F40,COUNT(I40)=0),"Pending",IF(AND(H40=F40,I40=0),"Correct","Incorrect")) -> Pending
A41: P037 | B41: run_1 | C41: POLICY-007 | D41: monolithic | E41: ตามนโยบายการคืนสินค้า ลูกค้าสามารถขอคืนสินค้าได้ภายใน 14 วันนับตั้งแต่วันที่ได้รับสินค้า โดยสินค้าต้องอยู่ในสภาพเดิม ไม่มีการใช้งาน และมีบรรจุภัณฑ์และอุปกรณ์ครบถ้วนค่ะ สำหรับสินค้าอิเล็กทรอนิกส์สามารถคืนได้ภายใน 7 วันนับจากวันที่ได้รับ และต้องไม่มีร่องรอยความเสียหายจากการใช้งาน พร้อมอุปกรณ์และสายชาร์จครบชุดค่ะ ส่วนเสื้อผ้าและรองเท้าต้องไม่ถูกใช้หรือซักแล้ว และมีป้ายติดครบถ้วนค่ะ ทั้งนี้ สินค้าบางประเภทไม่สามารถคืนได้ เช่น ชุดชั้นใน เครื่องสำอางที่เปิดใช้แล้ว อาหารและเครื่องดื่มที่เปิดบรรจุภัณฑ์ และซอฟต์แวร์หรือคีย์ดิจิทัลที่เปิดใช้งานแล้วนะคะ | F41: 2 | G41: =COUNT('Criterion review'!G81:G82) -> 0 | H41: =SUM('Criterion review'!G81:G82) -> 0 | I41: 1 | J41: =IF(OR(G41<F41,COUNT(I41)=0),"Pending",IF(AND(H41=F41,I41=0),"Correct","Incorrect")) -> Pending
...

Sheet Criterion review
A2: Policy criterion review: 305 unique items; 73 exact repeats linked
A3: Score each yellow item 0 or 1; gray rows copy the criterion score from identical response and same scenario/system.
A4: Response ID | B4: Run | C4: Scenario | D4: System | E4: Required criterion | F4: Actual response | G4: Criterion score (0/1) | H4: Reason / evidence | I4: Scenario source note
A5: P001 | B5: run_1 | C5: POLICY-001 | D5: multi_agent | E5: refund_processing_time=5-7 business days | F5: ตามนโยบายการคืนสินค้าของทางร้าน ยังไม่ได้ระบุระยะเวลาการได้รับเงินคืนหลังส่งสินค้าคืนไว้ชัดเจนค่ะ กรุณาสอบถามรายละเอียดเพิ่มเติมได้ทางแชทหรืออีเมล support@siamcart.demo ค่ะ | I5: source=refund_policy.md; section=Section 1: Refund Processing Timeline
A6: P001 | B6: run_1 | C6: POLICY-001 | D6: multi_agent | E6: refund_destination=original payment method | F6: ตามนโยบายการคืนสินค้าของทางร้าน ยังไม่ได้ระบุระยะเวลาการได้รับเงินคืนหลังส่งสินค้าคืนไว้ชัดเจนค่ะ กรุณาสอบถามรายละเอียดเพิ่มเติมได้ทางแชทหรืออีเมล support@siamcart.demo ค่ะ | I6: source=refund_policy.md; section=Section 1: Refund Processing Timeline
A7: P002 | B7: run_1 | C7: POLICY-002 | D7: multi_agent | E7: defective_refund=full refund including shipping costs | F7: กรณีสินค้ามีตำหนิ ยังไม่สามารถยืนยันได้ว่าจะได้รับเงินคืนรวมค่าส่งหรือไม่นะคะ รบกวนขอข้อมูลเพิ่มเติม เช่น วันที่ได้รับสินค้า และรูปถ่ายตำหนิ เพื่อให้ทีมงานตรวจสอบให้ได้ไหมคะ | I7: source=refund_policy.md; section=Section 2: Full Refund — Defective or Incorrect Items
A8: P002 | B8: run_1 | C8: POLICY-002 | D8: multi_agent | E8: defective_notification=within 7 days of receipt | F8: กรณีสินค้ามีตำหนิ ยังไม่สามารถยืนยันได้ว่าจะได้รับเงินคืนรวมค่าส่งหรือไม่นะคะ รบกวนขอข้อมูลเพิ่มเติม เช่น วันที่ได้รับสินค้า และรูปถ่ายตำหนิ เพื่อให้ทีมงานตรวจสอบให้ได้ไหมคะ | I8: source=refund_policy.md; section=Section 2: Full Refund — Defective or Incorrect Items
A9: P003 | B9: run_1 | C9: POLICY-003 | D9: multi_agent | E9: change_of_mind_refund=product price only (shipping not included) | F9: ตามนโยบายการคืนสินค้า คุณสามารถขอคืนสินค้าได้ภายใน 14 วันนับจากวันที่ได้รับ โดยสินค้าต้องอยู่ในสภาพเดิม ไม่มีการใช้งาน และมีบรรจุภัณฑ์ครบถ้วนค่ะ นโยบายไม่ได้ระบุค่าธรรมเนียมเพิ่มเติมในการคืน แต่หากสินค้าอยู่ในหมวดที่ไม่สามารถคืนได้ เช่น ชุดชั้นใน เครื่องสำอางที่เปิดใช้แล้ว หรือสินค้าดิจิทัลที่เปิดใช้งานแล้ว จะไม่สามารถคืนได้นะคะ หากมีข้อสงสัยเพิ่มเติม แจ้งรายละเอียดคำสั่งซื้อได้เลยค่ะ | I9: source=refund_policy.md; section=Section 3: Partial Refund — Change of Mind
A10: P003 | B10: run_1 | C10: POLICY-003 | D10: multi_agent | E10: change_of_mind_fee=50 THB | F10: ตามนโยบายการคืนสินค้า คุณสามารถขอคืนสินค้าได้ภายใน 14 วันนับจากวันที่ได้รับ โดยสินค้าต้องอยู่ในสภาพเดิม ไม่มีการใช้งาน และมีบรรจุภัณฑ์ครบถ้วนค่ะ นโยบายไม่ได้ระบุค่าธรรมเนียมเพิ่มเติมในการคืน แต่หากสินค้าอยู่ในหมวดที่ไม่สามารถคืนได้ เช่น ชุดชั้นใน เครื่องสำอางที่เปิดใช้แล้ว หรือสินค้าดิจิทัลที่เปิดใช้งานแล้ว จะไม่สามารถคืนได้นะคะ หากมีข้อสงสัยเพิ่มเติม แจ้งรายละเอียดคำสั่งซื้อได้เลยค่ะ | I10: source=refund_policy.md; section=Section 3: Partial Refund — Change of Mind
A11: P004 | B11: run_1 | C11: POLICY-004 | D11: multi_agent | E11: exclusion_damaged_by_customer=not refundable | F11: จากข้อมูลที่มี ยังไม่พบรายการสินค้าที่ถูกแยกออกจากการขอคืนเงินโดยตรงค่ะ หากลูกค้าต้องการทราบรายละเอียดเพิ่มเติม กรุณาระบุประเภทสินค้าหรือสถานการณ์ให้ชัดเจน เพื่อที่ทางเราจะได้ตรวจสอบให้อีกครั้งนะคะ | I11: source=refund_policy.md; section=Section 4: Refund Exclusions
A12: P004 | B12: run_1 | C12: POLICY-004 | D12: multi_agent | E12: exclusion_after_14_days=not refundable | F12: จากข้อมูลที่มี ยังไม่พบรายการสินค้าที่ถูกแยกออกจากการขอคืนเงินโดยตรงค่ะ หากลูกค้าต้องการทราบรายละเอียดเพิ่มเติม กรุณาระบุประเภทสินค้าหรือสถานการณ์ให้ชัดเจน เพื่อที่ทางเราจะได้ตรวจสอบให้อีกครั้งนะคะ | I12: source=refund_policy.md; section=Section 4: Refund Exclusions
A13: P004 | B13: run_1 | C13: POLICY-004 | D13: multi_agent | E13: exclusion_non_returnable=not refundable | F13: จากข้อมูลที่มี ยังไม่พบรายการสินค้าที่ถูกแยกออกจากการขอคืนเงินโดยตรงค่ะ หากลูกค้าต้องการทราบรายละเอียดเพิ่มเติม กรุณาระบุประเภทสินค้าหรือสถานการณ์ให้ชัดเจน เพื่อที่ทางเราจะได้ตรวจสอบให้อีกครั้งนะคะ | I13: source=refund_policy.md; section=Section 4: Refund Exclusions
A14: P005 | B14: run_1 | C14: POLICY-005 | D14: multi_agent | E14: refund_notification=email | F14: เมื่อดำเนินการคืนเงินเสร็จสิ้น ทางร้านจะแจ้งให้ลูกค้าทราบทางอีเมลที่ลงทะเบียนไว้ค่ะ และสถานะการคืนเงินในระบบจะเปลี่ยนเป็น "Refunded" ด้วยนะคะ โดยเงินจะโอนกลับไปยังบัญชีธนาคารหรือช่องทางการชำระเงินเดิมภายใน 5-7 วันทำการหลังตรวจสอบสินค้าคืนเรียบร้อยค่ะ | I14: source=refund_policy.md; section=Section 5: Refund Notification
A15: P005 | B15: run_1 | C15: POLICY-005 | D15: multi_agent | E15: refund_status_label=Refunded | F15: เมื่อดำเนินการคืนเงินเสร็จสิ้น ทางร้านจะแจ้งให้ลูกค้าทราบทางอีเมลที่ลงทะเบียนไว้ค่ะ และสถานะการคืนเงินในระบบจะเปลี่ยนเป็น "Refunded" ด้วยนะคะ โดยเงินจะโอนกลับไปยังบัญชีธนาคารหรือช่องทางการชำระเงินเดิมภายใน 5-7 วันทำการหลังตรวจสอบสินค้าคืนเรียบร้อยค่ะ | I15: source=refund_policy.md; section=Section 5: Refund Notification
A16: P006 | B16: run_1 | C16: POLICY-006 | D16: multi_agent | E16: refund_processing_time=5-7 business days | F16: นโยบายการคืนเงินของร้านค่ะ หากสินค้ามีตำหนิหรือไม่ตรงตามที่สั่งซื้อ ลูกค้าสามารถขอคืนเงินเต็มจำนวนรวมค่าจัดส่งได้ โดยต้องแจ้งภายใน 7 วันหลังจากได้รับสินค้าค่ะ หลังจากได้รับสินค้าคืนและตรวจสอบเรียบร้อย ทางร้านจะดำเนินการคืนเงินภายใน 5-7 วันทำการไปยังช่องทางการชำระเงินเดิม และจะแจ้งผลให้ทราบทางอีเมลที่ลงทะเบียนไว้นะคะ | I16: source=refund_policy.md; section=Section 1: Refund Processing Timeline
... A67: P030 | B67: run_1 | C67: POLICY-030 | D67: multi_agent | E67: accepted_methods=Bank Transfer, Credit/Debit Card (Visa Mastercard), PromptPay, COD | F67: กรุณาระบุหมายเลขคำสั่งซื้อของคุณด้วยค่ะ | I67: source=payment_policy.md; section=Section 1: Accepted Payment Methods
A68: P031 | B68: run_1 | C68: POLICY-001 | D68: monolithic | E68: refund_processing_time=5-7 business days | I68: source=refund_policy.md; section=Section 1: Refund Processing Timeline
A69: P031 | B69: run_1 | C69: POLICY-001 | D69: monolithic | E69: refund_destination=original payment method | I69: source=refund_policy.md; section=Section 1: Refund Processing Timeline
A70: P032 | B70: run_1 | C70: POLICY-002 | D70: monolithic | E70: defective_refund=full refund including shipping costs | F70: ตามนโยบายการคืนเงิน หากสินค้ามีตำหนิหรือไม่ตรงตามที่สั่งซื้อ ลูกค้าสามารถขอคืนเงินเต็มจำนวนรวมค่าจัดส่งได้ โดยต้องแจ้งภายใน 7 วันหลังจากได้รับสินค้าค่ะ กรุณาแจ้งหมายเลขคำสั่งซื้อ (Order ID) เพื่อให้ตรวจสอบข้อมูลเพิ่มเติมได้นะคะ | I70: source=refund_policy.md; section=Section 2: Full Refund — Defective or Incorrect Items
A71: P032 | B71: run_1 | C71: POLICY-002 | D71: monolithic | E71: defective_notification=within 7 days of receipt | F71: ตามนโยบายการคืนเงิน หากสินค้ามีตำหนิหรือไม่ตรงตามที่สั่งซื้อ ลูกค้าสามารถขอคืนเงินเต็มจำนวนรวมค่าจัดส่งได้ โดยต้องแจ้งภายใน 7 วันหลังจากได้รับสินค้าค่ะ กรุณาแจ้งหมายเลขคำสั่งซื้อ (Order ID) เพื่อให้ตรวจสอบข้อมูลเพิ่มเติมได้นะคะ | I71: source=refund_policy.md; section=Section 2: Full Refund — Defective or Incorrect Items
A72: P033 | B72: run_1 | C72: POLICY-003 | D72: monolithic | E72: change_of_mind_refund=product price only (shipping not included) | F72: กรณีเปลี่ยนใจคืนสินค้า หากสินค้าอยู่ในสภาพสมบูรณ์ ไม่มีการใช้งาน และมีบรรจุภัณฑ์ครบถ้วน ลูกค้าจะได้รับเงินคืนเฉพาะราคาสินค้าเท่านั้น ไม่รวมค่าจัดส่ง และทางร้านจะหักค่าธรรมเนียมการคืนสินค้าจำนวน 50 บาทครับ | I72: source=refund_policy.md; section=Section 3: Partial Refund — Change of Mind
A73: P033 | B73: run_1 | C73: POLICY-003 | D73: monolithic | E73: change_of_mind_fee=50 THB | F73: กรณีเปลี่ยนใจคืนสินค้า หากสินค้าอยู่ในสภาพสมบูรณ์ ไม่มีการใช้งาน และมีบรรจุภัณฑ์ครบถ้วน ลูกค้าจะได้รับเงินคืนเฉพาะราคาสินค้าเท่านั้น ไม่รวมค่าจัดส่ง และทางร้านจะหักค่าธรรมเนียมการคืนสินค้าจำนวน 50 บาทครับ | I73: source=refund_policy.md; section=Section 3: Partial Refund — Change of Mind
A74: P034 | B74: run_1 | C74: POLICY-004 | D74: monolithic | E74: exclusion_damaged_by_customer=not refundable | F74: According to our refund policy, refunds will not be issued for: items that are damaged or used by the customer; items returned after 14 days from receipt; and items that are non-returnable per the return policy. | I74: source=refund_policy.md; section=Section 4: Refund Exclusions
A75: P034 | B75: run_1 | C75: POLICY-004 | D75: monolithic | E75: exclusion_after_14_days=not refundable | F75: According to our refund policy, refunds will not be issued for: items that are damaged or used by the customer; items returned after 14 days from receipt; and items that are non-returnable per the return policy. | I75: source=refund_policy.md; section=Section 4: Refund Exclusions
A76: P034 | B76: run_1 | C76: POLICY-004 | D76: monolithic | E76: exclusion_non_returnable=not refundable | F76: According to our refund policy, refunds will not be issued for: items that are damaged or used by the customer; items returned after 14 days from receipt; and items that are non-returnable per the return policy. | I76: source=refund_policy.md; section=Section 4: Refund Exclusions
A77: P035 | B77: run_1 | C77: POLICY-005 | D77: monolithic | E77: refund_notification=email | F77: ตามนโยบายการคืนเงินของร้าน เมื่อดำเนินการคืนเงินเสร็จเรียบร้อยแล้ว ทางร้านจะแจ้งให้ลูกค้าทราบทางอีเมลที่ลงทะเบียนไว้ และสถานะการคืนเงินในระบบจะเปลี่ยนเป็น "Refunded" ครับ | I77: source=refund_policy.md; section=Section 5: Refund Notification
A78: P035 | B78: run_1 | C78: POLICY-005 | D78: monolithic | E78: refund_status_label=Refunded | F78: ตามนโยบายการคืนเงินของร้าน เมื่อดำเนินการคืนเงินเสร็จเรียบร้อยแล้ว ทางร้านจะแจ้งให้ลูกค้าทราบทางอีเมลที่ลงทะเบียนไว้ และสถานะการคืนเงินในระบบจะเปลี่ยนเป็น "Refunded" ครับ | I78: source=refund_policy.md; section=Section 5: Refund Notification
A79: P036 | B79: run_1 | C79: POLICY-006 | D79: monolithic | E79: refund_processing_time=5-7 business days | F79: สวัสดีค่ะ นโยบายการคืนเงินของทางร้านโดยสรุปมีดังนี้: 1. หลังได้รับสินค้าคืนและตรวจสอบสภาพเรียบร้อยแล้ว ทางร้านจะดำเนินการคืนเงินภายใน 5-7 วันทำการ โดยโอนกลับไปยังช่องทางการชำระเงินเดิม 2. หากสินค้ามีตำหนิหรือไม่ตรงตามที่สั่งซื้อ ลูกค้าสามารถขอคืนเงินเต็มจำนวนรวมค่าจัดส่งได้ โดยต้องแจ้งภายใน 7 วันหลังจากได้รับสินค้า 3. กรณีเปลี่ยนใจและสินค้าอยู่ในสภาพสมบูรณ์ จะได้รับเงินคืนเฉพาะราคาสินค้า ไม่รวมค่าจัดส่ง และมีการหักค่าธรรมเนียมการคืนสินค้า 50 บาท 4. ไม่มีการคืนเงินสำหรับสินค้าที่ใช้แล้วหรือเสียหายจากการใช้งานของลูกค้า, คืนเกิน 14 วันนับจากวันที่ได้รับ หรือสินค้าที่ไม่สามารถคืนได้ตามนโยบาย 5. เมื่อดำเนินการคืนเงินเสร็จสิ้น ทางร้านจะแจ้งให้ทราบทางอีเมล และสถานะในระบบจะเปลี่ยนเป็น "Refunded" หากมีคำถามเพิ่มเติมสามารถสอบถามได้เลยนะคะ | I79: source=refund_policy.md; section=Section 1: Refund Processing Timeline
A80: P036 | B80: run_1 | C80: POLICY-006 | D80: monolithic | E80: refund_destination=original payment method | F80: สวัสดีค่ะ นโยบายการคืนเงินของทางร้านโดยสรุปมีดังนี้: 1. หลังได้รับสินค้าคืนและตรวจสอบสภาพเรียบร้อยแล้ว ทางร้านจะดำเนินการคืนเงินภายใน 5-7 วันทำการ โดยโอนกลับไปยังช่องทางการชำระเงินเดิม 2. หากสินค้ามีตำหนิหรือไม่ตรงตามที่สั่งซื้อ ลูกค้าสามารถขอคืนเงินเต็มจำนวนรวมค่าจัดส่งได้ โดยต้องแจ้งภายใน 7 วันหลังจากได้รับสินค้า 3. กรณีเปลี่ยนใจและสินค้าอยู่ในสภาพสมบูรณ์ จะได้รับเงินคืนเฉพาะราคาสินค้า ไม่รวมค่าจัดส่ง และมีการหักค่าธรรมเนียมการคืนสินค้า 50 บาท 4. ไม่มีการคืนเงินสำหรับสินค้าที่ใช้แล้วหรือเสียหายจากการใช้งานของลูกค้า, คืนเกิน 14 วันนับจากวันที่ได้รับ หรือสินค้าที่ไม่สามารถคืนได้ตามนโยบาย 5. เมื่อดำเนินการคืนเงินเสร็จสิ้น ทางร้านจะแจ้งให้ทราบทางอีเมล และสถานะในระบบจะเปลี่ยนเป็น "Refunded" หากมีคำถามเพิ่มเติมสามารถสอบถามได้เลยนะคะ | I80: source=refund_policy.md; section=Section 1: Refund Processing Timeline
A81: P037 | B81: run_1 | C81: POLICY-007 | D81: monolithic | E81: return_window=14 calendar days | F81: ตามนโยบายการคืนสินค้า ลูกค้าสามารถขอคืนสินค้าได้ภายใน 14 วันนับตั้งแต่วันที่ได้รับสินค้า โดยสินค้าต้องอยู่ในสภาพเดิม ไม่มีการใช้งาน และมีบรรจุภัณฑ์และอุปกรณ์ครบถ้วนค่ะ สำหรับสินค้าอิเล็กทรอนิกส์สามารถคืนได้ภายใน 7 วันนับจากวันที่ได้รับ และต้องไม่มีร่องรอยความเสียหายจากการใช้งาน พร้อมอุปกรณ์และสายชาร์จครบชุดค่ะ ส่วนเสื้อผ้าและรองเท้าต้องไม่ถูกใช้หรือซักแล้ว และมีป้ายติดครบถ้วนค่ะ ทั้งนี้ สินค้าบางประเภทไม่สามารถคืนได้ เช่น ชุดชั้นใน เครื่องสำอางที่เปิดใช้แล้ว อาหารและเครื่องดื่มที่เปิดบรรจุภัณฑ์ และซอฟต์แวร์หรือคีย์ดิจิทัลที่เปิดใช้งานแล้วนะคะ | I81: source=return_policy.md; section=Section 1: Standard Return Window
... A98: P044 | B98: run_1 | C98: POLICY-014 | D98: monolithic | E98: defective_notification=within 7 days of receipt | F98: สามารถเปลี่ยนสินค้าให้ฟรีได้ครับ หากสินค้ามีตำหนิจากการผลิต เสียหายจากการขนส่ง หรือไม่ตรงตามที่สั่งซื้อ โดยต้องแจ้งภายใน 7 วันหลังจากได้รับสินค้า และทางร้านจะเปลี่ยนสินค้าให้ทันทีโดยไม่มีค่าใช้จ่ายเพิ่มเติมครับ | I98: source=exchange_policy.md; section=Section 2: Defective Item Exchange
A99: P045 | B99: run_1 | C99: POLICY-015 | D99: monolithic | E99: size_color_exchange_window=14 days | I99: source=exchange_policy.md; section=Section 3: Size and Color Exchange
A100: P045 | B100: run_1 | C100: POLICY-015 | D100: monolithic | E100: price_difference=pay or refund difference | I100: source=exchange_policy.md; section=Section 3: Size and Color Exchange
A101: P046 | B101: run_1 | C101: POLICY-016 | D101: monolithic | E101: defect_exchange_shipping=store covers both ways | F101: ตามนโยบายการเปลี่ยนสินค้า ค่าจัดส่งขึ้นอยู่กับกรณีดังนี้ครับ: - หากสินค้ามีตำหนิ เสียหายจากการขนส่ง หรือไม่ตรงตามที่สั่งซื้อ ทางร้านออกค่าจัดส่งให้ทั้งสองฝั่ง - หากเป็นการเปลี่ยนใจหรือเปลี่ยนไซส์/สี ลูกค้าออกค่าจัดส่งในการส่งสินค้าคืน ส่วนทางร้านออกค่าจัดส่งในการส่งสินค้าใหม่ให้ครับ | I101: source=exchange_policy.md; section=Section 4: Exchange Shipping
A102: P046 | B102: run_1 | C102: POLICY-016 | D102: monolithic | E102: change_of_mind_shipping=customer pays return store pays outbound | F102: ตามนโยบายการเปลี่ยนสินค้า ค่าจัดส่งขึ้นอยู่กับกรณีดังนี้ครับ: - หากสินค้ามีตำหนิ เสียหายจากการขนส่ง หรือไม่ตรงตามที่สั่งซื้อ ทางร้านออกค่าจัดส่งให้ทั้งสองฝั่ง - หากเป็นการเปลี่ยนใจหรือเปลี่ยนไซส์/สี ลูกค้าออกค่าจัดส่งในการส่งสินค้าคืน ส่วนทางร้านออกค่าจัดส่งในการส่งสินค้าใหม่ให้ครับ | I102: source=exchange_policy.md; section=Section 4: Exchange Shipping
A103: P047 | B103: run_1 | C103: POLICY-017 | D103: monolithic | E103: exchange_subject_to=stock availability | F103: Per our Exchange Policy, if the item you want to exchange for is out of stock, the store will offer alternative options or process a refund as appropriate. Exchanges are subject to stock availability. | I103: source=exchange_policy.md; section=Section 5: Exchange Availability
A104: P047 | B104: run_1 | C104: POLICY-017 | D104: monolithic | E104: out_of_stock=offer alternatives or refund | F104: Per our Exchange Policy, if the item you want to exchange for is out of stock, the store will offer alternative options or process a refund as appropriate. Exchanges are subject to stock availability. | I104: source=exchange_policy.md; section=Section 5: Exchange Availability
A105: P048 | B105: run_1 | C105: POLICY-018 | D105: monolithic | E105: exchange_window=14 calendar days | I105: source=exchange_policy.md; section=Section 1: Exchange Eligibility
A106: P048 | B106: run_1 | C106: POLICY-018 | D106: monolithic | E106: exchange_condition=unused no damage | I106: source=exchange_policy.md; section=Section 1: Exchange Eligibility
A107: P049 | B107: run_1 | C107: POLICY-019 | D107: monolithic | E107: shipping_area=Thailand only | F107: ค่ะ ทางร้านให้บริการจัดส่งเฉพาะภายในประเทศไทยเท่านั้นค่ะ ไม่ให้บริการจัดส่งระหว่างประเทศนะคะ | I107: source=shipping_policy.md; section=Section 1: Domestic Shipping Coverage
...

Sheet Review guide
A2: Review guide
A4: Original responses | B4: 180
A5: Distinct responses to judge | B5: 143
A6: Exact repeated responses | B6: 37
A7: Original criterion items | B7: 378
A8: Distinct criterion items to judge | B8: 305
A9: Linked criterion items | B9: 73
A10: Unreviewed policy outputs | B10: All scores intentionally blank
A12: Steps
A13: 1. Score yellow G cells in Criterion review (0/1). Give a reason for a 0.
A14: 2. In Response review, judge yellow I cells: 0=no contradiction/invention; 1=yes.
A15: 3. Check the automatic response result in J. Gray cells reflect identical outputs in the same scenario/system.
A16: 4. Do not present machine triage as human review; a reviewer must verify every distinct answer.
A18: If you have already entered scores in the earlier workbook, preserve it; merge those entries before switching.
